<?xml version="1.0" encoding="utf-8"?>
<!-- This URDF was automatically created by SolidWorks to URDF Exporter! Originally created by Stephen Brawner (brawner@gmail.com) 
     Commit Version: 1.6.0-4-g7f85cfe  Build Version: 1.6.7995.38578
     For more information, please see http://wiki.ros.org/sw_urdf_exporter -->
<robot
  name="Robot_arm_urdf">
  <link
    name="base_link">
    <inertial>
      <origin
        xyz="4.66E-05 -0.00023139 0.047897"
        rpy="0 0 0" />
      <mass
        value="2" />
      <inertia
        ixx="0.00013219"
        ixy="5.3372E-07"
        ixz="3.592E-08"
        iyy="0.00013378"
        iyz="-2.2201E-07"
        izz="0.00023169" />
    </inertial>
    <visual>
      <origin
        xyz="0 0 0"
        rpy="0 0 0" />
      <geometry>
        <mesh
          filename="package://Robot_arm_urdf/meshes/base_link.STL" />
      </geometry>
      <material
        name="">
        <color
          rgba="0.79216 0.81961 0.93333 1" />
      </material>
    </visual>
    <collision>
      <origin
        xyz="0 0 0"
        rpy="0 0 0" />
      <geometry>
        <mesh
          filename="package://Robot_arm_urdf/meshes/base_link.STL" />
      </geometry>
    </collision>
  </link>
  <joint
    name="joint_8"
    type="prismatic">
    <origin
      xyz="-0.00046176 0.010594 0.051243"
      rpy="0 -1.5708 0" />
    <parent
      link="link_6" />
    <child
      link="link_8" />
    <axis
      xyz="0 0 1" />
    <limit
      lower="-0.05"
      upper="0"
      effort="10"
      velocity="1" />
  </joint>
  <link
    name="link_1">
    <inertial>
      <origin
        xyz="0.015591 0.015767 0.020243"
        rpy="0 0 0" />
      <mass
        value="0.5" />
      <inertia
        ixx="0.0001518"
        ixy="-1.0373E-05"
        ixz="-1.8683E-05"
        iyy="0.0001313"
        iyz="-3.0671E-05"
        izz="0.00013359" />
    </inertial>
    <visual>
      <origin
        xyz="0 0 0"
        rpy="0 0 0" />
      <geometry>
        <mesh
          filename="package://Robot_arm_urdf/meshes/link_1.STL" />
      </geometry>
      <material
        name="">
        <color
          rgba="0.67843 0.7098 0.74118 1" />
      </material>
    </visual>
    <collision>
      <origin
        xyz="0 0 0"
        rpy="0 0 0" />
      <geometry>
        <mesh
          filename="package://Robot_arm_urdf/meshes/link_1.STL" />
      </geometry>
    </collision>
  </link>
  <joint
    name="joint_1"
    type="revolute">
    <origin
      xyz="0 0 0.0878"
      rpy="0.0019187 0.00060867 0" />
    <parent
      link="base_link" />
    <child
      link="link_1" />
    <axis
      xyz="0 0 -1" />
    <limit
      lower="-3.142"
      upper="3.142"
      effort="10"
      velocity="1" />
  </joint>
  <link
    name="link_2">
    <inertial>
      <origin
        xyz="-0.0074948 0.042767 0.021396"
        rpy="0 0 0" />
      <mass
        value="0.5" />
      <inertia
        ixx="0.00014302"
        ixy="2.6053E-05"
        ixz="2.193E-07"
        iyy="3.0551E-05"
        iyz="-2.516E-06"
        izz="0.00016565" />
    </inertial>
    <visual>
      <origin
        xyz="0 0 0"
        rpy="0 0 0" />
      <geometry>
        <mesh
          filename="package://Robot_arm_urdf/meshes/link_2.STL" />
      </geometry>
      <material
        name="">
        <color
          rgba="0.67843 0.7098 0.74118 1" />
      </material>
    </visual>
    <collision>
      <origin
        xyz="0 0 0"
        rpy="0 0 0" />
      <geometry>
        <mesh
          filename="package://Robot_arm_urdf/meshes/link_2.STL" />
      </geometry>
    </collision>
  </link>
  <joint
    name="joint_2"
    type="revolute">
    <origin
      xyz="0.0395 0.022932 0.0307"
      rpy="1.5708 -0.18881 1.5708" />
    <parent
      link="link_1" />
    <child
      link="link_2" />
    <axis
      xyz="0 0 1" />
    <limit
      lower="-1.57"
      upper="1.57"
      effort="10"
      velocity="1" />
  </joint>
  <link
    name="link_3">
    <inertial>
      <origin
        xyz="-0.0012254 -0.023702 -0.013849"
        rpy="0 0 0" />
      <mass
        value="0.5" />
      <inertia
        ixx="0.00023574"
        ixy="1.7763E-05"
        ixz="-2.2865E-06"
        iyy="0.00012779"
        iyz="4.8257E-08"
        izz="0.00027396" />
    </inertial>
    <visual>
      <origin
        xyz="0 0 0"
        rpy="0 0 0" />
      <geometry>
        <mesh
          filename="package://Robot_arm_urdf/meshes/link_3.STL" />
      </geometry>
      <material
        name="">
        <color
          rgba="0.67451 0.7098 0.73725 1" />
      </material>
    </visual>
    <collision>
      <origin
        xyz="0 0 0"
        rpy="0 0 0" />
      <geometry>
        <mesh
          filename="package://Robot_arm_urdf/meshes/link_3.STL" />
      </geometry>
    </collision>
  </link>
  <joint
    name="joint_3"
    type="revolute">
    <origin
      xyz="-0.018892 0.088122 0"
      rpy="0 0 2.9528" />
    <parent
      link="link_2" />
    <child
      link="link_3" />
    <axis
      xyz="0 0 1" />
    <limit
      lower="0"
      upper="3.142"
      effort="10"
      velocity="1" />
  </joint>
  <link
    name="link_4">
    <inertial>
      <origin
        xyz="0.0054005 2.0851E-05 0.046892"
        rpy="0 0 0" />
      <mass
        value="0.5" />
      <inertia
        ixx="1.1956E-05"
        ixy="-8.4642E-09"
        ixz="-2.9881E-07"
        iyy="1.6094E-05"
        iyz="-2.2836E-07"
        izz="1.491E-05" />
    </inertial>
    <visual>
      <origin
        xyz="0 0 0"
        rpy="0 0 0" />
      <geometry>
        <mesh
          filename="package://Robot_arm_urdf/meshes/link_4.STL" />
      </geometry>
      <material
        name="">
        <color
          rgba="0.67451 0.7098 0.73725 1" />
      </material>
    </visual>
    <collision>
      <origin
        xyz="0 0 0"
        rpy="0 0 0" />
      <geometry>
        <mesh
          filename="package://Robot_arm_urdf/meshes/link_4.STL" />
      </geometry>
    </collision>
  </link>
  <joint
    name="joint_4"
    type="revolute">
    <origin
      xyz="-0.057795 -0.055664 -0.01802"
      rpy="3.1416 -1.5708 0" />
    <parent
      link="link_3" />
    <child
      link="link_4" />
    <axis
      xyz="0 0 1" />
    <limit
      lower="0"
      upper="-3.142"
      effort="10"
      velocity="1" />
  </joint>
  <link
    name="link_5">
    <inertial>
      <origin
        xyz="0.04032 -8.192E-05 0.014292"
        rpy="0 0 0" />
      <mass
        value="0.35" />
      <inertia
        ixx="1.5523E-05"
        ixy="-1.8099E-08"
        ixz="7.6154E-06"
        iyy="4.471E-05"
        iyz="9.1786E-08"
        izz="3.8328E-05" />
    </inertial>
    <visual>
      <origin
        xyz="0 0 0"
        rpy="0 0 0" />
      <geometry>
        <mesh
          filename="package://Robot_arm_urdf/meshes/link_5.STL" />
      </geometry>
      <material
        name="">
        <color
          rgba="0.67451 0.7098 0.73725 1" />
      </material>
    </visual>
    <collision>
      <origin
        xyz="0 0 0"
        rpy="0 0 0" />
      <geometry>
        <mesh
          filename="package://Robot_arm_urdf/meshes/link_5.STL" />
      </geometry>
    </collision>
  </link>
  <joint
    name="joint_5"
    type="revolute">
    <origin
      xyz="0 1.594E-05 0.051214"
      rpy="1.5708 0 1.5708" />
    <parent
      link="link_4" />
    <child
      link="link_5" />
    <axis
      xyz="0 0 -1" />
    <limit
      lower="0"
      upper="3.142"
      effort="10"
      velocity="1" />
  </joint>
  <link
    name="link_6">
    <inertial>
      <origin
        xyz="2.7756E-17 0 0.014882"
        rpy="0 0 0" />
      <mass
        value="0.2" />
      <inertia
        ixx="1.5198E-06"
        ixy="-1.4332E-21"
        ixz="8.4363E-22"
        iyy="2.7551E-06"
        iyz="-8.4158E-22"
        izz="3.6228E-06" />
    </inertial>
    <visual>
      <origin
        xyz="0 0 0"
        rpy="0 0 0" />
      <geometry>
        <mesh
          filename="package://Robot_arm_urdf/meshes/link_6.STL" />
      </geometry>
      <material
        name="">
        <color
          rgba="0.67843 0.7098 0.74118 1" />
      </material>
    </visual>
    <collision>
      <origin
        xyz="0 0 0"
        rpy="0 0 0" />
      <geometry>
        <mesh
          filename="package://Robot_arm_urdf/meshes/link_6.STL" />
      </geometry>
    </collision>
  </link>
  <joint
    name="joint_6"
    type="revolute">
    <origin
      xyz="0.08 0 0.00037814"
      rpy="0 -1.5708 0" />
    <parent
      link="link_5" />
    <child
      link="link_6" />
    <axis
      xyz="0 0 1" />
    <limit
      lower="0"
      upper="3.142"
      effort="10"
      velocity="1" />
  </joint>
  <link
    name="link_7">
    <inertial>
      <origin
        xyz="-0.013095 0.010594 -0.0064025"
        rpy="0 0 0" />
      <mass
        value="0.05" />
      <inertia
        ixx="4.0118E-07"
        ixy="2.8245E-13"
        ixz="-1.0473E-07"
        iyy="7.2741E-07"
        iyz="6.0691E-14"
        izz="8.6735E-07" />
    </inertial>
    <visual>
      <origin
        xyz="0 0 0"
        rpy="0 0 0" />
      <geometry>
        <mesh
          filename="package://Robot_arm_urdf/meshes/link_7.STL" />
      </geometry>
      <material
        name="">
        <color
          rgba="0.67843 0.7098 0.74118 1" />
      </material>
    </visual>
    <collision>
      <origin
        xyz="0 0 0"
        rpy="0 0 0" />
      <geometry>
        <mesh
          filename="package://Robot_arm_urdf/meshes/link_7.STL" />
      </geometry>
    </collision>
  </link>
  <joint
    name="joint_7"
    type="prismatic">
    <origin
      xyz="0.00010176 -0.010594 0.051243"
      rpy="3.1416 -1.5708 0" />
    <parent
      link="link_6" />
    <child
      link="link_7" />
    <axis
      xyz="0 0 -1" />
    <limit
      lower="0"
      upper="0.05"
      effort="10"
      velocity="1" />
  </joint>
  <link
    name="link_8">
    <inertial>
      <origin
        xyz="-0.013095 0.010594 -0.0064025"
        rpy="0 0 0" />
      <mass
        value="0.05" />
      <inertia
        ixx="4.0118E-07"
        ixy="2.8245E-13"
        ixz="-1.0473E-07"
        iyy="7.2741E-07"
        iyz="6.0691E-14"
        izz="8.6735E-07" />
    </inertial>
    <visual>
      <origin
        xyz="0 0 0"
        rpy="0 0 0" />
      <geometry>
        <mesh
          filename="package://Robot_arm_urdf/meshes/link_8.STL" />
      </geometry>
      <material
        name="">
        <color
          rgba="0.67843 0.7098 0.74118 1" />
      </material>
    </visual>
    <collision>
      <origin
        xyz="0 0 0"
        rpy="0 0 0" />
      <geometry>
        <mesh
          filename="package://Robot_arm_urdf/meshes/link_8.STL" />
      </geometry>
    </collision>
  </link>
  <joint
    name="joint_8"
    type="prismatic">
    <origin
      xyz="-0.00046176 0.010594 0.051243"
      rpy="0 -1.5708 0" />
    <parent
      link="link_6" />
    <child
      link="link_8" />
    <axis
      xyz="0 0 1" />
    <limit
      lower="-0.05"
      upper="0"
      effort="10"
      velocity="1" />
  </joint>
</robot>