<?xml version="1.0" encoding="utf-8"?>
<!-- This URDF was automatically created by SolidWorks to URDF Exporter! Originally created by Stephen Brawner (brawner@gmail.com) 
     Commit Version: 1.6.0-4-g7f85cfe  Build Version: 1.6.7995.38578
     For more information, please see http://wiki.ros.org/sw_urdf_exporter -->
<robot
  name="robot_arm_urdf">


  <link name="world"/> 
  <joint name="base_joint" type="fixed"> 
  	<parent link="world"/> 
 	<child link="base_link"/> 
   	<origin rpy="0 0 0" xyz="0.0 0.0 0.01"/> 
  </joint> 

  <link
    name="base_link">
    <inertial>
      <origin
        xyz="-0.00031307 -7.1484E-05 0.049482"
        rpy="0 0 0" />
      <mass
        value="0.5" />
      <inertia
        ixx="0.0001335"
        ixy="-5.3356E-07"
        ixz="-3.382E-08"
        iyy="0.0001317"
        iyz="2.5679E-08"
        izz="0.00023102" />
    </inertial>
    <visual>
      <origin
        xyz="0 0 0"
        rpy="0 0 0" />
      <geometry>
        <mesh
          filename="package://03_NEW_ASS - v2/meshes/base_link.STL" />
      </geometry>
      <material
        name="">
        <color
          rgba="0.67451 0.7098 0.73725 1" />
      </material>
    </visual>
    <collision>
      <origin
        xyz="0 0 0"
        rpy="0 0 0" />
      <geometry>
        <mesh
          filename="package://03_NEW_ASS - v2/meshes/base_link.STL" />
      </geometry>
    </collision>
  </link>
  
  <link
    name="link_1">
    <inertial>
      <origin
        xyz="0.015798 -0.0156 0.037511"
        rpy="0 0 0" />
      <mass
        value="0.5" />
      <inertia
        ixx="0.00013121"
        ixy="1.0416E-05"
        ixz="-3.0662E-05"
        iyy="0.00015179"
        iyz="1.8675E-05"
        izz="0.0001337" />
    </inertial>
    <visual>
      <origin
        xyz="0 0 0"
        rpy="0 0 0" />
      <geometry>
        <mesh
          filename="package://03_NEW_ASS - v2/meshes/link_1.STL" />
      </geometry>
      <material
        name="">
        <color
          rgba="0.67843 0.7098 0.74118 1" />
      </material>
    </visual>
    <collision>
      <origin
        xyz="0 0 0"
        rpy="0 0 0" />
      <geometry>
        <mesh
          filename="package://03_NEW_ASS - v2/meshes/link_1.STL" />
      </geometry>
    </collision>
  </link>
  <joint
    name="joint_1"
    type="revolute">
    <origin
      xyz="2.6408E-05 0 0.0705"
      rpy="-0.00046854 -0.0015264 0" />
    <parent
      link="base_link" />
    <child
      link="link_1" />
    <axis
      xyz="-0.0015264 0.00046854 -1" />
    <limit
      lower="-3.142"
      upper="3.142"
      effort="10"
      velocity="1" />
  </joint>
  <link
    name="link_2">
    <inertial>
      <origin
        xyz="-0.0074948 0.042767 0.022315"
        rpy="0 0 0" />
      <mass
        value="0.5" />
      <inertia
        ixx="0.00014302"
        ixy="2.6053E-05"
        ixz="2.193E-07"
        iyy="3.0551E-05"
        iyz="-2.516E-06"
        izz="0.00016565" />
    </inertial>
    <visual>
      <origin
        xyz="0 0 0"
        rpy="0 0 0" />
      <geometry>
        <mesh
          filename="package://03_NEW_ASS - v2/meshes/link_2.STL" />
      </geometry>
      <material
        name="">
        <color
          rgba="0.67843 0.7098 0.74118 1" />
      </material>
    </visual>
    <collision>
      <origin
        xyz="0 0 0"
        rpy="0 0 0" />
      <geometry>
        <mesh
          filename="package://03_NEW_ASS - v2/meshes/link_2.STL" />
      </geometry>
    </collision>
  </link>
  <joint
    name="joint_2"
    type="revolute">
    <origin
      xyz="0.022979 -0.038595 0.047947"
      rpy="1.5713 0.0015264 0" />
    <parent
      link="link_1" />
    <child
      link="link_2" />
    <axis
      xyz="0 0 1" />
    <limit
      lower="-1.57"
      upper="1.57"
      effort="10"
      velocity="1" />
  </joint>
  <link
    name="link_3">
    <inertial>
      <origin
        xyz="-0.0012254 -0.023702 -0.01293"
        rpy="0 0 0" />
      <mass
        value="0.5" />
      <inertia
        ixx="0.00023574"
        ixy="1.7763E-05"
        ixz="-2.2865E-06"
        iyy="0.00012779"
        iyz="4.8257E-08"
        izz="0.00027396" />
    </inertial>
    <visual>
      <origin
        xyz="0 0 0"
        rpy="0 0 0" />
      <geometry>
        <mesh
          filename="package://03_NEW_ASS - v2/meshes/link_3.STL" />
      </geometry>
      <material
        name="">
        <color
          rgba="0.67451 0.7098 0.73725 1" />
      </material>
    </visual>
    <collision>
      <origin
        xyz="0 0 0"
        rpy="0 0 0" />
      <geometry>
        <mesh
          filename="package://03_NEW_ASS - v2/meshes/link_3.STL" />
      </geometry>
    </collision>
  </link>
  <joint
    name="joint_3"
    type="revolute">
    <origin
      xyz="-0.018892 0.088122 0"
      rpy="0 0 -3.1416" />
    <parent
      link="link_2" />
    <child
      link="link_3" />
    <axis
      xyz="0 0 1" />
    <limit
      lower="0"
      upper="1.57"
      effort="10"
      velocity="1" />
  </joint>
  <link
    name="link_4">
    <inertial>
      <origin
        xyz="0.0054005 2.0851E-05 0.04688"
        rpy="0 0 0" />
      <mass
        value="0.3" />
      <inertia
        ixx="1.1956E-05"
        ixy="-8.4642E-09"
        ixz="-2.9881E-07"
        iyy="1.6094E-05"
        iyz="-2.2836E-07"
        izz="1.491E-05" />
    </inertial>
    <visual>
      <origin
        xyz="0 0 0"
        rpy="0 0 0" />
      <geometry>
        <mesh
          filename="package://03_NEW_ASS - v2/meshes/link_4.STL" />
      </geometry>
      <material
        name="">
        <color
          rgba="0.67451 0.7098 0.73725 1" />
      </material>
    </visual>
    <collision>
      <origin
        xyz="0 0 0"
        rpy="0 0 0" />
      <geometry>
        <mesh
          filename="package://03_NEW_ASS - v2/meshes/link_4.STL" />
      </geometry>
    </collision>
  </link>
  <joint
    name="joint_4"
    type="revolute">
    <origin
      xyz="-0.057807 -0.055664 -0.017101"
      rpy="3.1416 -1.5708 0" />
    <parent
      link="link_3" />
    <child
      link="link_4" />
    <axis
      xyz="0 0 1" />
    <limit
      lower="-1.57"
      upper="0"
      effort="10"
      velocity="1" />
  </joint>
  <link
    name="link_5">
    <inertial>
      <origin
        xyz="0.04032 -0.00043783 0.014285"
        rpy="0 0 0" />
      <mass
        value="0.25" />
      <inertia
        ixx="1.5523E-05"
        ixy="-2.0775E-07"
        ixz="7.6126E-06"
        iyy="4.4701E-05"
        iyz="2.5057E-07"
        izz="3.8336E-05" />
    </inertial>
    <visual>
      <origin
        xyz="0 0 0"
        rpy="0 0 0" />
      <geometry>
        <mesh
          filename="package://03_NEW_ASS - v2/meshes/link_5.STL" />
      </geometry>
      <material
        name="">
        <color
          rgba="0.67451 0.7098 0.73725 1" />
      </material>
    </visual>
    <collision>
      <origin
        xyz="0 0 0"
        rpy="0 0 0" />
      <geometry>
        <mesh
          filename="package://03_NEW_ASS - v2/meshes/link_5.STL" />
      </geometry>
    </collision>
  </link>
  <joint
    name="joint_5"
    type="revolute">
    <origin
      xyz="0 1.594E-05 0.051203"
      rpy="1.5459 0 1.5708" />
    <parent
      link="link_4" />
    <child
      link="link_5" />
    <axis
      xyz="0 0.024905 -0.99969" />
    <limit
      lower="0"
      upper="1.57"
      effort="10"
      velocity="1" />
  </joint>
  <link
    name="link_6">
    <inertial>
      <origin
        xyz="1.3878E-17 0 0.014882"
        rpy="0 0 0" />
      <mass
        value="0.25" />
      <inertia
        ixx="1.5198E-06"
        ixy="-6.2204E-22"
        ixz="9.7579E-22"
        iyy="2.7551E-06"
        iyz="-1.2158E-21"
        izz="3.6228E-06" />
    </inertial>
    <visual>
      <origin
        xyz="0 0 0"
        rpy="0 0 0" />
      <geometry>
        <mesh
          filename="package://03_NEW_ASS - v2/meshes/link_6.STL" />
      </geometry>
      <material
        name="">
        <color
          rgba="0.67843 0.7098 0.74118 1" />
      </material>
    </visual>
    <collision>
      <origin
        xyz="0 0 0"
        rpy="0 0 0" />
      <geometry>
        <mesh
          filename="package://03_NEW_ASS - v2/meshes/link_6.STL" />
      </geometry>
    </collision>
  </link>
  <joint
    name="joint_6"
    type="revolute">
    <origin
      xyz="0.08 0 0.00037802"
      rpy="1.5708 -1.5457 1.5708" />
    <parent
      link="link_5" />
    <child
      link="link_6" />
    <axis
      xyz="0 0 1" />
    <limit
      lower="0"
      upper="1.57"
      effort="10"
      velocity="1" />
  </joint>
  <link
    name="link_7">
    <inertial>
      <origin
        xyz="0.013095 -0.00060083 -0.0067555"
        rpy="0 0 0" />
      <mass
        value="0.05" />
      <inertia
        ixx="4.0118E-07"
        ixy="2.8245E-13"
        ixz="1.0473E-07"
        iyy="7.2741E-07"
        iyz="-6.0691E-14"
        izz="8.6735E-07" />
    </inertial>
    <visual>
      <origin
        xyz="0 0 0"
        rpy="0 0 0" />
      <geometry>
        <mesh
          filename="package://03_NEW_ASS - v2/meshes/link_7.STL" />
      </geometry>
      <material
        name="">
        <color
          rgba="0.67843 0.7098 0.74118 1" />
      </material>
    </visual>
    <collision>
      <origin
        xyz="0 0 0"
        rpy="0 0 0" />
      <geometry>
        <mesh
          filename="package://03_NEW_ASS - v2/meshes/link_7.STL" />
      </geometry>
    </collision>
  </link>
  <joint
    name="joint_7"
    type="prismatic">
    <origin
      xyz="-0.00078273 -0.00060084 0.051243"
      rpy="3.1416 1.5708 0" />
    <parent
      link="link_6" />
    <child
      link="link_7" />
    <axis
      xyz="0 0 -1" />
    <limit
      lower="0"
      upper="0.05"
      effort="10"
      velocity="1" />
  </joint>
  <link
    name="link_8">
    <inertial>
      <origin
        xyz="0.013095 -0.00017073 -0.0047359"
        rpy="0 0 0" />
      <mass
        value="0.05" />
      <inertia
        ixx="4.0118E-07"
        ixy="-7.8608E-09"
        ixz="1.0444E-07"
        iyy="7.282E-07"
        iyz="-1.0474E-08"
        izz="8.6656E-07" />
    </inertial>
    <visual>
      <origin
        xyz="0 0 0"
        rpy="0 0 0" />
      <geometry>
        <mesh
          filename="package://03_NEW_ASS - v2/meshes/link_8.STL" />
      </geometry>
      <material
        name="">
        <color
          rgba="0.67843 0.7098 0.74118 1" />
      </material>
    </visual>
    <collision>
      <origin
        xyz="0 0 0"
        rpy="0 0 0" />
      <geometry>
        <mesh
          filename="package://03_NEW_ASS - v2/meshes/link_8.STL" />
      </geometry>
    </collision>
  </link>
  <joint
    name="joint_8"
    type="prismatic">
    <origin
      xyz="-0.001623 0.00052571 0.051243"
      rpy="0.075128 1.5708 0" />
    <parent
      link="link_6" />
    <child
      link="link_8" />
    <axis
      xyz="0 -0.075058 0.99718" />
    <limit
      lower="-0.05"
      upper="0"
      effort="10"
      velocity="1" />
  </joint>

<transmission name="link_1_trans"> 
 	<type>transmission_interface/SimpleTransmission</type> 
 	<joint name="joint_1"> 
 
 	<hardwareInterface>hardware_interface/PositionJointInterface</hardwareInterface> 
 	</joint> 
 	<actuator name="link_1_motor"> 
 
 	<hardwareInterface>hardware_interface/PositionJointInterface</hardwareInterface> 
  	<mechanicalReduction>1</mechanicalReduction> 
 	</actuator> 
</transmission>

<transmission name="link_2_trans"> 
 	<type>transmission_interface/SimpleTransmission</type> 
 	<joint name="joint_2"> 
 
 	<hardwareInterface>hardware_interface/PositionJointInterface</hardwareInterface> 
 	</joint> 
 	<actuator name="link_2_motor"> 
 
 	<hardwareInterface>hardware_interface/PositionJointInterface</hardwareInterface> 
  	<mechanicalReduction>1</mechanicalReduction> 
 	</actuator> 
</transmission>

<transmission name="link_3_trans"> 
 	<type>transmission_interface/SimpleTransmission</type> 
 	<joint name="joint_3"> 
 
 	<hardwareInterface>hardware_interface/PositionJointInterface</hardwareInterface> 
 	</joint> 
 	<actuator name="link_3_motor"> 
 
 	<hardwareInterface>hardware_interface/PositionJointInterface</hardwareInterface> 
  	<mechanicalReduction>1</mechanicalReduction> 
 	</actuator> 
</transmission>

<transmission name="link_4_trans"> 
 	<type>transmission_interface/SimpleTransmission</type> 
 	<joint name="joint_4"> 
 
 	<hardwareInterface>hardware_interface/PositionJointInterface</hardwareInterface> 
 	</joint> 
 	<actuator name="link_4_motor"> 
 
 	<hardwareInterface>hardware_interface/PositionJointInterface</hardwareInterface> 
  	<mechanicalReduction>1</mechanicalReduction> 
 	</actuator> 
</transmission>

<transmission name="link_5_trans"> 
 	<type>transmission_interface/SimpleTransmission</type> 
 	<joint name="joint_5"> 
 
 	<hardwareInterface>hardware_interface/PositionJointInterface</hardwareInterface> 
 	</joint> 
 	<actuator name="link_5_motor"> 
 
 	<hardwareInterface>hardware_interface/PositionJointInterface</hardwareInterface> 
  	<mechanicalReduction>1</mechanicalReduction> 
 	</actuator> 
</transmission>

<transmission name="link_6_trans"> 
 	<type>transmission_interface/SimpleTransmission</type> 
 	<joint name="joint_6"> 
 
 	<hardwareInterface>hardware_interface/PositionJointInterface</hardwareInterface> 
 	</joint> 
 	<actuator name="link_6_motor"> 
 
 	<hardwareInterface>hardware_interface/PositionJointInterface</hardwareInterface> 
  	<mechanicalReduction>1</mechanicalReduction> 
 	</actuator> 
</transmission>

<transmission name="link_7_trans"> 
 	<type>transmission_interface/SimpleTransmission</type> 
 	<joint name="joint_7"> 
 
 	<hardwareInterface>hardware_interface/PositionJointInterface</hardwareInterface> 
 	</joint> 
 	<actuator name="link_7_motor"> 
 
 	<hardwareInterface>hardware_interface/PositionJointInterface</hardwareInterface> 
  	<mechanicalReduction>1</mechanicalReduction> 
 	</actuator> 
</transmission>

<transmission name="link_8_trans"> 
 	<type>transmission_interface/SimpleTransmission</type> 
 	<joint name="joint_8"> 
 
 	<hardwareInterface>hardware_interface/PositionJointInterface</hardwareInterface> 
 	</joint> 
 	<actuator name="link_8_motor"> 
 
 	<hardwareInterface>hardware_interface/PositionJointInterface</hardwareInterface> 
  	<mechanicalReduction>1</mechanicalReduction> 
 	</actuator> 
</transmission>

 <gazebo> 
   	<plugin name="control" filename="libgazebo_ros_control.so"> 
  		<robotNamespace>/</robotNamespace> 
 	</plugin> 
 </gazebo> 

  <gazebo reference="link_1"> 
     	<selfCollide>true</selfCollide> 
  </gazebo> 

  <gazebo reference="link_2"> 
     	<selfCollide>true</selfCollide> 
  </gazebo> 

  <gazebo reference="link_3"> 
     	<selfCollide>true</selfCollide> 
  </gazebo> 

  <gazebo reference="link_4"> 
     	<selfCollide>true</selfCollide> 
  </gazebo> 

  <gazebo reference="link_5"> 
     	<selfCollide>true</selfCollide> 
  </gazebo> 

  <gazebo reference="link_6"> 
     	<selfCollide>true</selfCollide> 
  </gazebo> 

  <gazebo reference="link_7"> 
     	<selfCollide>true</selfCollide> 
  </gazebo> 

  <gazebo reference="link_8"> 
     	<selfCollide>true</selfCollide> 
  </gazebo> 

</robot>